Workbook

Sheet Customer Names
A1: Customer ID | B1: name | C1: Title | D1: First name | E1: LastName
A2: Id1 | B2: Hawks, Ms. Kelly | C2: =TRIM(MID(B2,FIND(",",B2)+1,FIND(".",B2)-FIND(",",B2))) -> Ms. | D2: =TRIM(MID(B2,FIND(".",B2)+1,LEN(B2))) -> Kelly | E2: =TRIM(LEFT(B2,FIND(",",B2)-1)) -> Hawks
A3: Id2 | B3: Lehner, Mr. Matthew D | C3: =TRIM(MID(B3,FIND(",",B3)+1,FIND(".",B3)-FIND(",",B3))) -> Mr. | D3: =TRIM(MID(B3,FIND(".",B3)+1,LEN(B3))) -> Matthew D | E3: =TRIM(LEFT(B3,FIND(",",B3)-1)) -> Lehner
A4: Id3 | B4: Lu, Mr. Phil | C4: =TRIM(MID(B4,FIND(",",B4)+1,FIND(".",B4)-FIND(",",B4))) -> Mr. | D4: =TRIM(MID(B4,FIND(".",B4)+1,LEN(B4))) -> Phil | E4: =TRIM(LEFT(B4,FIND(",",B4)-1)) -> Lu
A5: Id4 | B5: Osborne, Ms. Kelsey | C5: =TRIM(MID(B5,FIND(",",B5)+1,FIND(".",B5)-FIND(",",B5))) -> Ms. | D5: =TRIM(MID(B5,FIND(".",B5)+1,LEN(B5))) -> Kelsey | E5: =TRIM(LEFT(B5,FIND(",",B5)-1)) -> Osborne
A6: Id5 | B6: Kadala, Ms. Kristyn | C6: =TRIM(MID(B6,FIND(",",B6)+1,FIND(".",B6)-FIND(",",B6))) -> Ms. | D6: =TRIM(MID(B6,FIND(".",B6)+1,LEN(B6))) -> Kristyn | E6: =TRIM(LEFT(B6,FIND(",",B6)-1)) -> Kadala
A7: Id6 | B7: Baker, Mr. Russell B. | C7: =TRIM(MID(B7,FIND(",",B7)+1,FIND(".",B7)-FIND(",",B7))) -> Mr. | D7: =TRIM(MID(B7,FIND(".",B7)+1,LEN(B7))) -> Russell B. | E7: =TRIM(LEFT(B7,FIND(",",B7)-1)) -> Baker
A8: Id7 | B8: Macpherson, Mr. Scott | C8: =TRIM(MID(B8,FIND(",",B8)+1,FIND(".",B8)-FIND(",",B8))) -> Mr. | D8: =TRIM(MID(B8,FIND(".",B8)+1,LEN(B8))) -> Scott | E8: =TRIM(LEFT(B8,FIND(",",B8)-1)) -> Macpherson
A9: Id8 | B9: Hallman, Mr. Stephen | C9: =TRIM(MID(B9,FIND(",",B9)+1,FIND(".",B9)-FIND(",",B9))) -> Mr. | D9: =TRIM(MID(B9,FIND(".",B9)+1,LEN(B9))) -> Stephen | E9: =TRIM(LEFT(B9,FIND(",",B9)-1)) -> Hallman
A10: Id9 | B10: Moran, Mr. Patrick R. | C10: =TRIM(MID(B10,FIND(",",B10)+1,FIND(".",B10)-FIND(",",B10))) -> Mr. | D10: =TRIM(MID(B10,FIND(".",B10)+1,LEN(B10))) -> Patrick R. | E10: =TRIM(LEFT(B10,FIND(",",B10)-1)) -> Moran
A11: Id10 | B11: Benner, Ms. Brooke N. | C11: =TRIM(MID(B11,FIND(",",B11)+1,FIND(".",B11)-FIND(",",B11))) -> Ms. | D11: =TRIM(MID(B11,FIND(".",B11)+1,LEN(B11))) -> Brooke N. | E11: =TRIM(LEFT(B11,FIND(",",B11)-1)) -> Benner
A12: Id11 | B12: Fierro Vargas, Ms. Paola Andrea | C12: =TRIM(MID(B12,FIND(",",B12)+1,FIND(".",B12)-FIND(",",B12))) -> Ms. | D12: =TRIM(MID(B12,FIND(".",B12)+1,LEN(B12))) -> Paola Andrea | E12: =TRIM(LEFT(B12,FIND(",",B12)-1)) -> Fierro Vargas
A13: Id12 | B13: Franz, Mr. David | C13: =TRIM(MID(B13,FIND(",",B13)+1,FIND(".",B13)-FIND(",",B13))) -> Mr. | D13: =TRIM(MID(B13,FIND(".",B13)+1,LEN(B13))) -> David | E13: =TRIM(LEFT(B13,FIND(",",B13)-1)) -> Franz
... A2336: Id2335 | B2336: German, Mr. Aaron K | C2336: =TRIM(MID(B2336,FIND(",",B2336)+1,FIND(".",B2336)-FIND(",",B2336))) -> Mr. | D2336: =TRIM(MID(B2336,FIND(".",B2336)+1,LEN(B2336))) -> Aaron K | E2336: =TRIM(LEFT(B2336,FIND(",",B2336)-1)) -> German

Sheet Medical Examinations
A1: Customer ID | B1: Weight status | C1: BMI | D1: HBA1C | E1: Diabetes status | F1: Heart Issues | G1: Any Transplants | H1: Cancer history | I1: NumberOfMajorSurgeries | J1: smoker
A2: Id1 | B2: =IF(C2<18.5,"Underweight",IF(C2<25,"Normal Weight",IF(C2<30,"Overweight","Obesity"))) -> Obesity | C2: 47.41 | D2: 7.47 | E2: =IF(D2<5.7,"Normal",IF(D2<6.5,"Prediabetes","Diabetes")) -> Diabetes | F2: No | G2: No | H2: No | I2: =IF(I2="No major surgery",0,VALUE(I2)) -> 0 | J2: yes
A3: Id2 | B3: =IF(C3<18.5,"Underweight",IF(C3<25,"Normal Weight",IF(C3<30,"Overweight","Obesity"))) -> Obesity | C3: 30.36 | D3: 5.77 | E3: =IF(D3<5.7,"Normal",IF(D3<6.5,"Prediabetes","Diabetes")) -> Prediabetes | F3: No | G3: No | H3: No | I3: =IF(I3="No major surgery",0,VALUE(I3)) -> 0 | J3: yes
A4: Id3 | B4: =IF(C4<18.5,"Underweight",IF(C4<25,"Normal Weight",IF(C4<30,"Overweight","Obesity"))) -> Obesity | C4: 34.485 | D4: 11.87 | E4: =IF(D4<5.7,"Normal",IF(D4<6.5,"Prediabetes","Diabetes")) -> Diabetes | F4: yes | G4: No | H4: No | I4: 2 | J4: yes
A5: Id4 | B5: =IF(C5<18.5,"Underweight",IF(C5<25,"Normal Weight",IF(C5<30,"Overweight","Obesity"))) -> Obesity | C5: 38.095 | D5: 6.05 | E5: =IF(D5<5.7,"Normal",IF(D5<6.5,"Prediabetes","Diabetes")) -> Prediabetes | F5: No | G5: No | H5: No | I5: =IF(I2="No major surgery",0,VALUE(I2)) -> 0 | J5: yes
A6: Id5 | B6: =IF(C6<18.5,"Underweight",IF(C6<25,"Normal Weight",IF(C6<30,"Overweight","Obesity"))) -> Obesity | C6: 35.53 | D6: 5.45 | E6: =IF(D6<5.7,"Normal",IF(D6<6.5,"Prediabetes","Diabetes")) -> Normal | F6: No | G6: No | H6: No | I6: =IF(I3="No major surgery",0,VALUE(I3)) -> 0 | J6: yes
A7: Id6 | B7: =IF(C7<18.5,"Underweight",IF(C7<25,"Normal Weight",IF(C7<30,"Overweight","Obesity"))) -> Obesity | C7: 32.8 | D7: 6.59 | E7: =IF(D7<5.7,"Normal",IF(D7<6.5,"Prediabetes","Diabetes")) -> Diabetes | F7: No | G7: No | H7: No | I7: =IF(I4="No major surgery",0,VALUE(I4)) -> 2 | J7: yes
A8: Id7 | B8: =IF(C8<18.5,"Underweight",IF(C8<25,"Normal Weight",IF(C8<30,"Overweight","Obesity"))) -> Obesity | C8: 36.4 | D8: 6.07 | E8: =IF(D8<5.7,"Normal",IF(D8<6.5,"Prediabetes","Diabetes")) -> Prediabetes | F8: No | G8: No | H8: No | I8: =IF(I5="No major surgery",0,VALUE(I5)) -> 0 | J8: yes
A9: Id8 | B9: =IF(C9<18.5,"Underweight",IF(C9<25,"Normal Weight",IF(C9<30,"Overweight","Obesity"))) -> Obesity | C9: 36.96 | D9: 7.93 | E9: =IF(D9<5.7,"Normal",IF(D9<6.5,"Prediabetes","Diabetes")) -> Diabetes | F9: No | G9: No | H9: No | I9: 3 | J9: yes
A10: Id9 | B10: =IF(C10<18.5,"Underweight",IF(C10<25,"Normal Weight",IF(C10<30,"Overweight","Obesity"))) -> Obesity | C10: 41.14 | D10: 9.58 | E10: =IF(D10<5.7,"Normal",IF(D10<6.5,"Prediabetes","Diabetes")) -> Diabetes | F10: yes | G10: No | H10: Yes | I10: 1 | J10: yes
A11: Id10 | B11: =IF(C11<18.5,"Underweight",IF(C11<25,"Normal Weight",IF(C11<30,"Overweight","Obesity"))) -> Obesity | C11: 38.06 | D11: 10.79 | E11: =IF(D11<5.7,"Normal",IF(D11<6.5,"Prediabetes","Diabetes")) -> Diabetes | F11: No | G11: No | H11: No | I11: =IF(I2="No major surgery",0,VALUE(I2)) -> 0 | J11: yes
A12: Id11 | B12: =IF(C12<18.5,"Underweight",IF(C12<25,"Normal Weight",IF(C12<30,"Overweight","Obesity"))) -> Obesity | C12: 37.7 | D12: 5.96 | E12: =IF(D12<5.7,"Normal",IF(D12<6.5,"Prediabetes","Diabetes")) -> Prediabetes | F12: yes | G12: No | H12: No | I12: =IF(I3="No major surgery",0,VALUE(I3)) -> 0 | J12: yes
A13: Id12 | B13: =IF(C13<18.5,"Underweight",IF(C13<25,"Normal Weight",IF(C13<30,"Overweight","Obesity"))) -> Obesity | C13: 42.13 | D13: 11.9 | E13: =IF(D13<5.7,"Normal",IF(D13<6.5,"Prediabetes","Diabetes")) -> Diabetes | F13: No | G13: No | H13: No | I13: =IF(I4="No major surgery",0,VALUE(I4)) -> 2 | J13: yes
A14: Id13 | B14: =IF(C14<18.5,"Underweight",IF(C14<25,"Normal Weight",IF(C14<30,"Overweight","Obesity"))) -> Obesity | C14: 40.92 | D14: 8.41 | E14: =IF(D14<5.7,"Normal",IF(D14<6.5,"Prediabetes","Diabetes")) -> Diabetes | F14: No | G14: No | H14: No | I14: =IF(I5="No major surgery",0,VALUE(I5)) -> 0 | J14: yes
A15: Id14 | B15: =IF(C15<18.5,"Underweight",IF(C15<25,"Normal Weight",IF(C15<30,"Overweight","Obesity"))) -> Obesity | C15: 40.565 | D15: 7.02 | E15: =IF(D15<5.7,"Normal",IF(D15<6.5,"Prediabetes","Diabetes")) -> Diabetes | F15: No | G15: No | H15: No | I15: =IF(I6="No major surgery",0,VALUE(I6)) -> 0 | J15: yes
A16: Id15 | B16: =IF(C16<18.5,"Underweight",IF(C16<25,"Normal Weight",IF(C16<30,"Overweight","Obesity"))) -> Obesity | C16: 36.385 | D16: 7.59 | E16: =IF(D16<5.7,"Normal",IF(D16<6.5,"Prediabetes","Diabetes")) -> Diabetes | F16: yes | G16: No | H16: No | I16: =IF(I7="No major surgery",0,VALUE(I7)) -> 2 | J16: yes
A17: Id16 | B17: =IF(C17<18.5,"Underweight",IF(C17<25,"Normal Weight",IF(C17<30,"Overweight","Obesity"))) -> Obesity | C17: 39.9 | D17: 11.32 | E17: =IF(D17<5.7,"Normal",IF(D17<6.5,"Prediabetes","Diabetes")) -> Diabetes | F17: No | G17: No | H17: No | I17: =IF(I8="No major surgery",0,VALUE(I8)) -> 2 | J17: yes
A18: Id17 | B18: =IF(C18<18.5,"Underweight",IF(C18<25,"Normal Weight",IF(C18<30,"Overweight","Obesity"))) -> Obesity | C18: 33.8 | D18: 7.67 | E18: =IF(D18<5.7,"Normal",IF(D18<6.5,"Prediabetes","Diabetes")) -> Diabetes | F18: No | G18: No | H18: No | I18: =IF(I9="No major surgery",0,VALUE(I9)) -> 3 | J18: yes
A19: Id18 | B19: =IF(C19<18.5,"Underweight",IF(C19<25,"Normal Weight",IF(C19<30,"Overweight","Obesity"))) -> Obesity | C19: 36.765 | D19: 7.29 | E19: =IF(D19<5.7,"Normal",IF(D19<6.5,"Prediabetes","Diabetes")) -> Diabetes | F19: yes | G19: No | H19: Yes | I19: =IF(I10="No major surgery",0,VALUE(I10)) -> 1 | J19: yes
A20: Id19 | B20: =IF(C20<18.5,"Underweight",IF(C20<25,"Normal Weight",IF(C20<30,"Overweight","Obesity"))) -> Obesity | C20: 36.955 | D20: 4.72 | E20: =IF(D20<5.7,"Normal",IF(D20<6.5,"Prediabetes","Diabetes")) -> Normal | F20: yes | G20: No | H20: No | I20: 1 | J20: yes
A21: Id20 | B21: =IF(C21<18.5,"Underweight",IF(C21<25,"Normal Weight",IF(C21<30,"Overweight","Obesity"))) -> Obesity | C21: 42.9 | D21: 11.41 | E21: =IF(D21<5.7,"Normal",IF(D21<6.5,"Prediabetes","Diabetes")) -> Diabetes | F21: No | G21: No | H21: No | I21: =IF(I2="No major surgery",0,VALUE(I2)) -> 0 | J21: yes
A22: Id21 | B22: =IF(C22<18.5,"Underweight",IF(C22<25,"Normal Weight",IF(C22<30,"Overweight","Obesity"))) -> Obesity | C22: 36.3 | D22: 11.5 | E22: =IF(D22<5.7,"Normal",IF(D22<6.5,"Prediabetes","Diabetes")) -> Diabetes | F22: yes | G22: No | H22: No | I22: 2 | J22: yes
A23: Id22 | B23: =IF(C23<18.5,"Underweight",IF(C23<25,"Normal Weight",IF(C23<30,"Overweight","Obesity"))) -> Obesity | C23: 32.2 | D23: 6.22 | E23: =IF(D23<5.7,"Normal",IF(D23<6.5,"Prediabetes","Diabetes")) -> Prediabetes | F23: yes | G23: No | H23: No | I23: 2 | J23: yes
A24: Id23 | B24: =IF(C24<18.5,"Underweight",IF(C24<25,"Normal Weight",IF(C24<30,"Overweight","Obesity"))) -> Obesity | C24: 31.3 | D24: 11.38 | E24: =IF(D24<5.7,"Normal",IF(D24<6.5,"Prediabetes","Diabetes")) -> Diabetes | F24: No | G24: No | H24: No | I24: 3 | J24: yes
A25: Id24 | B25: =IF(C25<18.5,"Underweight",IF(C25<25,"Normal Weight",IF(C25<30,"Overweight","Obesity"))) -> Obesity | C25: 41.8 | D25: 7.89 | E25: =IF(D25<5.7,"Normal",IF(D25<6.5,"Prediabetes","Diabetes")) -> Diabetes | F25: yes | G25: No | H25: No | I25: 2 | J25: yes
A26: Id25 | B26: =IF(C26<18.5,"Underweight",IF(C26<25,"Normal Weight",IF(C26<30,"Overweight","Obesity"))) -> Obesity | C26: 35.09 | D26: 4.38 | E26: =IF(D26<5.7,"Normal",IF(D26<6.5,"Prediabetes","Diabetes")) -> Normal | F26: yes | G26: No | H26: No | I26: 2 | J26: yes
A27: Id26 | B27: =IF(C27<18.5,"Underweight",IF(C27<25,"Normal Weight",IF(C27<30,"Overweight","Obesity"))) -> Obesity | C27: 33.88 | D27: 7.01 | E27: =IF(D27<5.7,"Normal",IF(D27<6.5,"Prediabetes","Diabetes")) -> Diabetes | F27: No | G27: No | H27: No | I27: 3 | J27: yes
A28: Id27 | B28: =IF(C28<18.5,"Underweight",IF(C28<25,"Normal Weight",IF(C28<30,"Overweight","Obesity"))) -> Obesity | C28: 30.875 | D28: 11.88 | E28: =IF(D28<5.7,"Normal",IF(D28<6.5,"Prediabetes","Diabetes")) -> Diabetes | F28: No | G28: No | H28: No | I28: =IF(I2="No major surgery",0,VALUE(I2)) -> 0 | J28: yes
A29: Id28 | B29: =IF(C29<18.5,"Underweight",IF(C29<25,"Normal Weight",IF(C29<30,"Overweight","Obesity"))) -> Obesity | C29: 36.86 | D29: 5.19 | E29: =IF(D29<5.7,"Normal",IF(D29<6.5,"Prediabetes","Diabetes")) -> Normal | F29: yes | G29: No | H29: Yes | I29: 1 | J29: yes
A30: Id29 | B30: =IF(C30<18.5,"Underweight",IF(C30<25,"Normal Weight",IF(C30<30,"Overweight","Obesity"))) -> Obesity | C30: 35.86 | D30: 6.74 | E30: =IF(D30<5.7,"Normal",IF(D30<6.5,"Prediabetes","Diabetes")) -> Diabetes | F30: yes | G30: No | H30: No | I30: =IF(I4="No major surgery",0,VALUE(I4)) -> 2 | J30: yes
A31: Id30 | B31: =IF(C31<18.5,"Underweight",IF(C31<25,"Normal Weight",IF(C31<30,"Overweight","Obesity"))) -> Obesity | C31: 37.05 | D31: 8.44 | E31: =IF(D31<5.7,"Normal",IF(D31<6.5,"Prediabetes","Diabetes")) -> Diabetes | F31: No | G31: No | H31: No | I31: =IF(I5="No major surgery",0,VALUE(I5)) -> 0 | J31: yes
A32: Id31 | B32: =IF(C32<18.5,"Underweight",IF(C32<25,"Normal Weight",IF(C32<30,"Overweight","Obesity"))) -> Obesity | C32: 43.89 | D32: 8.71 | E32: =IF(D32<5.7,"Normal",IF(D32<6.5,"Prediabetes","Diabetes")) -> Diabetes | F32: No | G32: No | H32: No | I32: =IF(I6="No major surgery",0,VALUE(I6)) -> 0 | J32: yes
A33: Id32 | B33: =IF(C33<18.5,"Underweight",IF(C33<25,"Normal Weight",IF(C33<30,"Overweight","Obesity"))) -> Obesity | C33: 42.35 | D33: 5.08 | E33: =IF(D33<5.7,"Normal",IF(D33<6.5,"Prediabetes","Diabetes")) -> Normal | F33: yes | G33: No | H33: No | I33: =IF(I7="No major surgery",0,VALUE(I7)) -> 2 | J33: yes
A34: Id33 | B34: =IF(C34<18.5,"Underweight",IF(C34<25,"Normal Weight",IF(C34<30,"Overweight","Obesity"))) -> Obesity | C34: 31.35 | D34: 6.86 | E34: =IF(D34<5.7,"Normal",IF(D34<6.5,"Prediabetes","Diabetes")) -> Diabetes | F34: No | G34: No | H34: No | I34: =IF(I8="No major surgery",0,VALUE(I8)) -> 0 | J34: yes
A35: Id34 | B35: =IF(C35<18.5,"Underweight",IF(C35<25,"Normal Weight",IF(C35<30,"Overweight","Obesity"))) -> Obesity | C35: 47.6 | D35: 5.95 | E35: =IF(D35<5.7,"Normal",IF(D35<6.5,"Prediabetes","Diabetes")) -> Prediabetes | F35: yes | G35: No | H35: No | I35: =IF(I9="No major surgery",0,VALUE(I9)) -> 3 | J35: yes
A36: Id35 | B36: =IF(C36<18.5,"Underweight",IF(C36<25,"Normal Weight",IF(C36<30,"Overweight","Obesity"))) -> Obesity | C36: 46.2 | D36: 6.09 | E36: =IF(D36<5.7,"Normal",IF(D36<6.5,"Prediabetes","Diabetes")) -> Prediabetes | F36: No | G36: No | H36: Yes | I36: 1 | J36: yes
A37: Id36 | B37: =IF(C37<18.5,"Underweight",IF(C37<25,"Normal Weight",IF(C37<30,"Overweight","Obesity"))) -> Obesity | C37: 32.015 | D37: 11.75 | E37: =IF(D37<5.7,"Normal",IF(D37<6.5,"Prediabetes","Diabetes")) -> Diabetes | F37: No | G37: No | H37: No | I37: =IF(I2="No major surgery",0,VALUE(I2)) -> 0 | J37: yes
A38: Id37 | B38: =IF(C38<18.5,"Underweight",IF(C38<25,"Normal Weight",IF(C38<30,"Overweight","Obesity"))) -> Obesity | C38: 40.565 | D38: 7.37 | E38: =IF(D38<5.7,"Normal",IF(D38<6.5,"Prediabetes","Diabetes")) -> Diabetes | F38: No | G38: No | H38: No | I38: =IF(I3="No major surgery",0,VALUE(I3)) -> 0 | J38: yes
A39: Id38 | B39: =IF(C39<18.5,"Underweight",IF(C39<25,"Normal Weight",IF(C39<30,"Overweight","Obesity"))) -> Obesity | C39: 32.45 | D39: 11.91 | E39: =IF(D39<5.7,"Normal",IF(D39<6.5,"Prediabetes","Diabetes")) -> Diabetes | F39: No | G39: No | H39: No | I39: =IF(I4="No major surgery",0,VALUE(I4)) -> 2 | J39: yes
A40: Id39 | B40: =IF(C40<18.5,"Underweight",IF(C40<25,"Normal Weight",IF(C40<30,"Overweight","Obesity"))) -> Obesity | C40: 34.96 | D40: 6.52 | E40: =IF(D40<5.7,"Normal",IF(D40<6.5,"Prediabetes","Diabetes")) -> Diabetes | F40: No | G40: No | H40: No | I40: =IF(I5="No major surgery",0,VALUE(I5)) -> 0 | J40: yes
...

Sheet Hospitalisation Details
A1: Customer ID | B1: year | C1: month | D1: date | E1: children | F1: charges | G1: Hospital tier | H1: City tier | I1: State ID | J1: Date of birth | K1: Age | N1: 45085 | O1: collection date
A2: Id2335 | B2: 1992 | C2: Jul | D2: 9 | E2: 0 | F2: 563.84 | G2: tier - 2 | H2: tier - 3 | I2: R1013 | J2: =DATE(B2,MATCH(C2,{"Jan","Feb","Mar","Apr","May","Jun","Jul","Aug","Sep","Oct","Nov","Dec"},0),D2) -> 33794 | K2: =DATEDIF(J2,$N$1,"Y") -> 30
A3: Id2334 | B3: 1992 | C3: Nov | D3: 30 | E3: 0 | F3: 570.62 | G3: tier - 2 | H3: tier - 1 | I3: R1013 | J3: =DATE(B3,MATCH(C3,{"Jan","Feb","Mar","Apr","May","Jun","Jul","Aug","Sep","Oct","Nov","Dec"},0),D3) -> 33938 | K3: =DATEDIF(J3,$N$1,"Y") -> 30
A4: Id2333 | B4: 1993 | C4: Jun | D4: 30 | E4: 0 | F4: 600 | G4: tier - 2 | H4: tier - 1 | I4: R1013 | J4: =DATE(B4,MATCH(C4,{"Jan","Feb","Mar","Apr","May","Jun","Jul","Aug","Sep","Oct","Nov","Dec"},0),D4) -> 34150 | K4: =DATEDIF(J4,$N$1,"Y") -> 29
A5: Id2332 | B5: 1992 | C5: Sep | D5: 13 | E5: 0 | F5: 604.54 | G5: tier - 3 | H5: tier - 3 | I5: R1013 | J5: =DATE(B5,MATCH(C5,{"Jan","Feb","Mar","Apr","May","Jun","Jul","Aug","Sep","Oct","Nov","Dec"},0),D5) -> 33860 | K5: =DATEDIF(J5,$N$1,"Y") -> 30
A6: Id2331 | B6: 1998 | C6: Jul | D6: 27 | E6: 0 | F6: 637.26 | G6: tier - 3 | H6: tier - 3 | I6: R1013 | J6: =DATE(B6,MATCH(C6,{"Jan","Feb","Mar","Apr","May","Jun","Jul","Aug","Sep","Oct","Nov","Dec"},0),D6) -> 36003 | K6: =DATEDIF(J6,$N$1,"Y") -> 24
A7: Id2330 | B7: 2001 | C7: Nov | D7: 20 | E7: 0 | F7: 646.14 | G7: tier - 3 | H7: tier - 3 | I7: R1012 | J7: =DATE(B7,MATCH(C7,{"Jan","Feb","Mar","Apr","May","Jun","Jul","Aug","Sep","Oct","Nov","Dec"},0),D7) -> 37215 | K7: =DATEDIF(J7,$N$1,"Y") -> 21
A8: Id2329 | B8: 1993 | C8: Jun | D8: 1 | E8: 0 | F8: 650 | G8: tier - 3 | H8: tier - 3 | I8: R1013 | J8: =DATE(B8,MATCH(C8,{"Jan","Feb","Mar","Apr","May","Jun","Jul","Aug","Sep","Oct","Nov","Dec"},0),D8) -> 34121 | K8: =DATEDIF(J8,$N$1,"Y") -> 30
A9: Id2328 | B9: 1995 | C9: Jul | D9: 4 | E9: 0 | F9: 650 | G9: tier - 3 | H9: tier - 3 | I9: R1013 | J9: =DATE(B9,MATCH(C9,{"Jan","Feb","Mar","Apr","May","Jun","Jul","Aug","Sep","Oct","Nov","Dec"},0),D9) -> 34884 | K9: =DATEDIF(J9,$N$1,"Y") -> 27
A10: Id2327 | B10: 2002 | C10: Nov | D10: 29 | E10: 0 | F10: 668 | G10: tier - 3 | H10: tier - 2 | I10: R1012 | J10: =DATE(B10,MATCH(C10,{"Jan","Feb","Mar","Apr","May","Jun","Jul","Aug","Sep","Oct","Nov","Dec"},0),D10) -> 37589 | K10: =DATEDIF(J10,$N$1,"Y") -> 20
A11: Id2326 | B11: 1997 | C11: Nov | D11: 9 | E11: 0 | F11: 670 | G11: tier - 3 | H11: tier - 3 | I11: R1013 | J11: =DATE(B11,MATCH(C11,{"Jan","Feb","Mar","Apr","May","Jun","Jul","Aug","Sep","Oct","Nov","Dec"},0),D11) -> 35743 | K11: =DATEDIF(J11,$N$1,"Y") -> 25
A12: Id2325 | B12: 2001 | C12: Sep | D12: 12 | E12: 0 | F12: 687.54 | G12: tier - 3 | H12: tier - 2 | I12: R1013 | J12: =DATE(B12,MATCH(C12,{"Jan","Feb","Mar","Apr","May","Jun","Jul","Aug","Sep","Oct","Nov","Dec"},0),D12) -> 37146 | K12: =DATEDIF(J12,$N$1,"Y") -> 21
A13: Id2324 | B13: 1999 | C13: Dec | D13: 26 | E13: 0 | F13: 700 | G13: tier - 2 | H13: tier - 3 | I13: R1013 | J13: =DATE(B13,MATCH(C13,{"Jan","Feb","Mar","Apr","May","Jun","Jul","Aug","Sep","Oct","Nov","Dec"},0),D13) -> 36520 | K13: =DATEDIF(J13,$N$1,"Y") -> 23
... A2344: Id1 | B2344: 1968 | C2344: Oct | D2344: 12 | E2344: 0 | F2344: 63770.43 | G2344: tier - 1 | H2344: tier - 3 | I2344: R1013 | J2344: =DATE(B2344,MATCH(C2344,{"Jan","Feb","Mar","Apr","May","Jun","Jul","Aug","Sep","Oct","Nov","Dec"},0),D2344) -> 25123 | K2344: =DATEDIF(J2344,$N$1,"Y") -> 54
A2345: =COUNTIF(A2:A2344,"?") -> 6 | B2345: 0 | C2345: =COUNTIF(C2:C2344,"?") -> 0 | D2345: =COUNTIF(D2:D2344,"?") -> 0 | E2345: =COUNTIF(E2:E2344,"?") -> 0 | F2345: =COUNTIF(F2:F2344,"?") -> 0 | G2345: =COUNTIF(G2:G2344,"?") -> 0 | H2345: =COUNTIF(H2:H2344,"?") -> 0 | I2345: =COUNTIF(I2:I2344,"?") -> 0
B2346: =ROUND(AVERAGE(B2:B2344),0) -> 1983 | G2346: {=INDEX(H2:H2336, MODE(MATCH(H2:H2336,H2:H2336,0)))} -> tier - 2 | H2346: {=INDEX(H2:H2336, MODE(MATCH(H2:H2336,H2:H2336,0)))} -> tier - 2
B2347: averge

Sheet Healthcare
A1: Customer ID | B1: Customer ID | C1: First name | D1: Weight Status | E1: HBA1C | F1: Heart issues | G1: Any transplants | H1: Cancer history | I1: NumberOfMajorSurgeries | J1: smoker | K1: Diabetes status | L1: BMI | M1: charges | N1: D.O.B | O1: City tier | P1: Hospitaltier | Q1: State ID | R1: Age
A2: Id1 | B2: Id2335 | C2: =VLOOKUP($A2,'Customer Names'!$A:$E,4,FALSE) -> Kelly | D2: =VLOOKUP($A2,'Medical Examinations'!$A:$J,2,FALSE) -> Obesity | E2: =VLOOKUP($A2,'Medical Examinations'!$A:$J,4,FALSE) -> 7.47 | F2: =VLOOKUP($A2,'Medical Examinations'!$A:$J,6,FALSE) -> No | G2: No | H2: =VLOOKUP($A2,'Medical Examinations'!$A:$J,8,FALSE) -> No | I2: =VLOOKUP($A2,'Medical Examinations'!$A:$J,9,FALSE) -> 0 | J2: =VLOOKUP($A2,'Medical Examinations'!$A:$J,10,FALSE) -> yes | K2: =VLOOKUP($A2,'Medical Examinations'!$A:$J,5,FALSE) -> Diabetes | L2: =VLOOKUP($A3,'Medical Examinations'!$A:$J,3,FALSE) -> 30.36 | M2: =VLOOKUP($A2,'Hospitalisation Details'!$A:$K,6,FALSE) -> 63770.43 | N2: =R2 -> 30 | O2: =VLOOKUP($B2,'Hospitalisation Details'!A1:J2345,8,0) -> tier - 3 | P2: =VLOOKUP($B2,'Hospitalisation Details'!A1:J2345,7,0) -> tier - 2 | Q2: =VLOOKUP($B2,'Hospitalisation Details'!A1:J2345,9,0) -> R1013 | R2: =VLOOKUP($B2,'Hospitalisation Details'!A1:K2345,11,0) -> 30
A3: Id2 | B3: Id2334 | C3: =VLOOKUP($A3,'Customer Names'!$A:$E,4,FALSE) -> Matthew D | D3: =VLOOKUP($A3,'Medical Examinations'!$A:$J,2,FALSE) -> Obesity | E3: =VLOOKUP($A3,'Medical Examinations'!$A:$J,4,FALSE) -> 5.77 | F3: =VLOOKUP($A3,'Medical Examinations'!$A:$J,6,FALSE) -> No | G3: =VLOOKUP($A3,'Medical Examinations'!$A:$J,7,FALSE) -> No | H3: =VLOOKUP($A3,'Medical Examinations'!$A:$J,8,FALSE) -> No | I3: =VLOOKUP($A3,'Medical Examinations'!$A:$J,9,FALSE) -> 0 | J3: =VLOOKUP($A3,'Medical Examinations'!$A:$J,10,FALSE) -> yes | K3: =VLOOKUP($A3,'Medical Examinations'!$A:$J,5,FALSE) -> Prediabetes | L3: =VLOOKUP($A4,'Medical Examinations'!$A:$J,3,FALSE) -> 34.485 | M3: =VLOOKUP($A3,'Hospitalisation Details'!$A:$K,6,FALSE) -> 62592.87 | N3: =VLOOKUP($B3,'Hospitalisation Details'!A2:J2346,10,0) -> 33938 | O3: =VLOOKUP($B3,'Hospitalisation Details'!A2:J2346,8,0) -> tier - 1 | P3: =VLOOKUP($B3,'Hospitalisation Details'!A2:J2346,7,0) -> tier - 2 | Q3: =VLOOKUP($B3,'Hospitalisation Details'!A2:J2346,9,0) -> R1013 | R3: =VLOOKUP($B3,'Hospitalisation Details'!A2:K2346,11,0) -> 30
A4: Id3 | B4: Id2333 | C4: =VLOOKUP($A4,'Customer Names'!$A:$E,4,FALSE) -> Phil | D4: =VLOOKUP($A4,'Medical Examinations'!$A:$J,2,FALSE) -> Obesity | E4: =VLOOKUP($A4,'Medical Examinations'!$A:$J,4,FALSE) -> 11.87 | F4: =VLOOKUP($A4,'Medical Examinations'!$A:$J,6,FALSE) -> yes | G4: =VLOOKUP($A4,'Medical Examinations'!$A:$J,7,FALSE) -> No | H4: =VLOOKUP($A4,'Medical Examinations'!$A:$J,8,FALSE) -> No | I4: =VLOOKUP($A4,'Medical Examinations'!$A:$J,9,FALSE) -> 2 | J4: =VLOOKUP($A4,'Medical Examinations'!$A:$J,10,FALSE) -> yes | K4: =VLOOKUP($A4,'Medical Examinations'!$A:$J,5,FALSE) -> Diabetes | L4: =VLOOKUP($A5,'Medical Examinations'!$A:$J,3,FALSE) -> 38.095 | M4: =VLOOKUP($A4,'Hospitalisation Details'!$A:$K,6,FALSE) -> 60021.4 | N4: =VLOOKUP($B4,'Hospitalisation Details'!A3:J2347,10,0) -> 34150 | O4: =VLOOKUP($B4,'Hospitalisation Details'!A3:J2347,8,0) -> tier - 1 | P4: =VLOOKUP($B4,'Hospitalisation Details'!A3:J2347,7,0) -> tier - 2 | Q4: =VLOOKUP($B4,'Hospitalisation Details'!A3:J2347,9,0) -> R1013 | R4: =VLOOKUP($B4,'Hospitalisation Details'!A3:K2347,11,0) -> 29
A5: Id4 | B5: Id2332 | C5: =VLOOKUP($A5,'Customer Names'!$A:$E,4,FALSE) -> Kelsey | D5: =VLOOKUP($A5,'Medical Examinations'!$A:$J,2,FALSE) -> Obesity | E5: =VLOOKUP($A5,'Medical Examinations'!$A:$J,4,FALSE) -> 6.05 | F5: =VLOOKUP($A5,'Medical Examinations'!$A:$J,6,FALSE) -> No | G5: =VLOOKUP($A5,'Medical Examinations'!$A:$J,7,FALSE) -> No | H5: =VLOOKUP($A5,'Medical Examinations'!$A:$J,8,FALSE) -> No | I5: =VLOOKUP($A5,'Medical Examinations'!$A:$J,9,FALSE) -> 0 | J5: =VLOOKUP($A5,'Medical Examinations'!$A:$J,10,FALSE) -> yes | K5: =VLOOKUP($A5,'Medical Examinations'!$A:$J,5,FALSE) -> Prediabetes | L5: =VLOOKUP($A6,'Medical Examinations'!$A:$J,3,FALSE) -> 35.53 | M5: =VLOOKUP($A5,'Hospitalisation Details'!$A:$K,6,FALSE) -> 58571.07 | N5: =VLOOKUP($B5,'Hospitalisation Details'!A4:J2348,10,0) -> 33860 | O5: =VLOOKUP($B5,'Hospitalisation Details'!A4:J2348,8,0) -> tier - 3 | P5: =VLOOKUP($B5,'Hospitalisation Details'!A4:J2348,7,0) -> tier - 3 | Q5: =VLOOKUP($B5,'Hospitalisation Details'!A4:J2348,9,0) -> R1013 | R5: =VLOOKUP($B5,'Hospitalisation Details'!A4:K2348,11,0) -> 30
A6: Id5 | B6: Id2331 | C6: =VLOOKUP($A6,'Customer Names'!$A:$E,4,FALSE) -> Kristyn | D6: =VLOOKUP($A6,'Medical Examinations'!$A:$J,2,FALSE) -> Obesity | E6: =VLOOKUP($A6,'Medical Examinations'!$A:$J,4,FALSE) -> 5.45 | F6: =VLOOKUP($A6,'Medical Examinations'!$A:$J,6,FALSE) -> No | G6: =VLOOKUP($A6,'Medical Examinations'!$A:$J,7,FALSE) -> No | H6: =VLOOKUP($A6,'Medical Examinations'!$A:$J,8,FALSE) -> No | I6: =VLOOKUP($A6,'Medical Examinations'!$A:$J,9,FALSE) -> 0 | J6: =VLOOKUP($A6,'Medical Examinations'!$A:$J,10,FALSE) -> yes | K6: =VLOOKUP($A6,'Medical Examinations'!$A:$J,5,FALSE) -> Normal | L6: =VLOOKUP($A7,'Medical Examinations'!$A:$J,3,FALSE) -> 32.8 | M6: =VLOOKUP($A6,'Hospitalisation Details'!$A:$K,6,FALSE) -> 55135.4 | N6: =VLOOKUP($B6,'Hospitalisation Details'!A5:J2349,10,0) -> 36003 | O6: =VLOOKUP($B6,'Hospitalisation Details'!A5:J2349,8,0) -> tier - 3 | P6: =VLOOKUP($B6,'Hospitalisation Details'!A5:J2349,7,0) -> tier - 3 | Q6: =VLOOKUP($B6,'Hospitalisation Details'!A5:J2349,9,0) -> R1013 | R6: =VLOOKUP($B6,'Hospitalisation Details'!A5:K2349,11,0) -> 24
A7: Id6 | B7: Id2330 | C7: =VLOOKUP($A7,'Customer Names'!$A:$E,4,FALSE) -> Russell B. | D7: =VLOOKUP($A7,'Medical Examinations'!$A:$J,2,FALSE) -> Obesity | E7: =VLOOKUP($A7,'Medical Examinations'!$A:$J,4,FALSE) -> 6.59 | F7: =VLOOKUP($A7,'Medical Examinations'!$A:$J,6,FALSE) -> No | G7: =VLOOKUP($A7,'Medical Examinations'!$A:$J,7,FALSE) -> No | H7: =VLOOKUP($A7,'Medical Examinations'!$A:$J,8,FALSE) -> No | I7: =VLOOKUP($A7,'Medical Examinations'!$A:$J,9,FALSE) -> 2 | J7: =VLOOKUP($A7,'Medical Examinations'!$A:$J,10,FALSE) -> yes | K7: =VLOOKUP($A7,'Medical Examinations'!$A:$J,5,FALSE) -> Diabetes | L7: =VLOOKUP($A8,'Medical Examinations'!$A:$J,3,FALSE) -> 36.4 | M7: =VLOOKUP($A7,'Hospitalisation Details'!$A:$K,6,FALSE) -> 52590.83 | N7: =VLOOKUP($B7,'Hospitalisation Details'!A6:J2350,10,0) -> 37215 | O7: =VLOOKUP($B7,'Hospitalisation Details'!A6:J2350,8,0) -> tier - 3 | P7: =VLOOKUP($B7,'Hospitalisation Details'!A6:J2350,7,0) -> tier - 3 | Q7: =VLOOKUP($B7,'Hospitalisation Details'!A6:J2350,9,0) -> R1012 | R7: =VLOOKUP($B7,'Hospitalisation Details'!A6:K2350,11,0) -> 21
A8: Id7 | B8: Id2329 | C8: =VLOOKUP($A8,'Customer Names'!$A:$E,4,FALSE) -> Scott | D8: =VLOOKUP($A8,'Medical Examinations'!$A:$J,2,FALSE) -> Obesity | E8: =VLOOKUP($A8,'Medical Examinations'!$A:$J,4,FALSE) -> 6.07 | F8: =VLOOKUP($A8,'Medical Examinations'!$A:$J,6,FALSE) -> No | G8: =VLOOKUP($A8,'Medical Examinations'!$A:$J,7,FALSE) -> No | H8: =VLOOKUP($A8,'Medical Examinations'!$A:$J,8,FALSE) -> No | I8: =VLOOKUP($A8,'Medical Examinations'!$A:$J,9,FALSE) -> 0 | J8: =VLOOKUP($A8,'Medical Examinations'!$A:$J,10,FALSE) -> yes | K8: =VLOOKUP($A8,'Medical Examinations'!$A:$J,5,FALSE) -> Prediabetes | L8: =VLOOKUP($A9,'Medical Examinations'!$A:$J,3,FALSE) -> 36.96 | M8: =VLOOKUP($A8,'Hospitalisation Details'!$A:$K,6,FALSE) -> 51194.56 | N8: =VLOOKUP($B8,'Hospitalisation Details'!A7:J2351,10,0) -> 34121 | O8: =VLOOKUP($B8,'Hospitalisation Details'!A7:J2351,8,0) -> tier - 3 | P8: =VLOOKUP($B8,'Hospitalisation Details'!A7:J2351,7,0) -> tier - 3 | Q8: =VLOOKUP($B8,'Hospitalisation Details'!A7:J2351,9,0) -> R1013 | R8: =VLOOKUP($B8,'Hospitalisation Details'!A7:K2351,11,0) -> 30
A9: Id8 | B9: Id2328 | C9: =VLOOKUP($A9,'Customer Names'!$A:$E,4,FALSE) -> Stephen | D9: =VLOOKUP($A9,'Medical Examinations'!$A:$J,2,FALSE) -> Obesity | E9: =VLOOKUP($A9,'Medical Examinations'!$A:$J,4,FALSE) -> 7.93 | F9: =VLOOKUP($A9,'Medical Examinations'!$A:$J,6,FALSE) -> No | G9: =VLOOKUP($A9,'Medical Examinations'!$A:$J,7,FALSE) -> No | H9: =VLOOKUP($A9,'Medical Examinations'!$A:$J,8,FALSE) -> No | I9: =VLOOKUP($A9,'Medical Examinations'!$A:$J,9,FALSE) -> 3 | J9: =VLOOKUP($A9,'Medical Examinations'!$A:$J,10,FALSE) -> yes | K9: =VLOOKUP($A9,'Medical Examinations'!$A:$J,5,FALSE) -> Diabetes | L9: =VLOOKUP($A10,'Medical Examinations'!$A:$J,3,FALSE) -> 41.14 | M9: =VLOOKUP($A9,'Hospitalisation Details'!$A:$K,6,FALSE) -> 49577.66 | N9: =VLOOKUP($B9,'Hospitalisation Details'!A8:J2352,10,0) -> 34884 | O9: =VLOOKUP($B9,'Hospitalisation Details'!A8:J2352,8,0) -> tier - 3 | P9: =VLOOKUP($B9,'Hospitalisation Details'!A8:J2352,7,0) -> tier - 3 | Q9: =VLOOKUP($B9,'Hospitalisation Details'!A8:J2352,9,0) -> R1013 | R9: =VLOOKUP($B9,'Hospitalisation Details'!A8:K2352,11,0) -> 27
A10: Id9 | B10: Id2327 | C10: =VLOOKUP($A10,'Customer Names'!$A:$E,4,FALSE) -> Patrick R. | D10: =VLOOKUP($A10,'Medical Examinations'!$A:$J,2,FALSE) -> Obesity | E10: =VLOOKUP($A10,'Medical Examinations'!$A:$J,4,FALSE) -> 9.58 | F10: =VLOOKUP($A10,'Medical Examinations'!$A:$J,6,FALSE) -> yes | G10: =VLOOKUP($A10,'Medical Examinations'!$A:$J,7,FALSE) -> No | H10: =VLOOKUP($A10,'Medical Examinations'!$A:$J,8,FALSE) -> Yes | I10: =VLOOKUP($A10,'Medical Examinations'!$A:$J,9,FALSE) -> 1 | J10: =VLOOKUP($A10,'Medical Examinations'!$A:$J,10,FALSE) -> yes | K10: =VLOOKUP($A10,'Medical Examinations'!$A:$J,5,FALSE) -> Diabetes | L10: =VLOOKUP($A11,'Medical Examinations'!$A:$J,3,FALSE) -> 38.06 | M10: =VLOOKUP($A10,'Hospitalisation Details'!$A:$K,6,FALSE) -> 48970.25 | N10: =VLOOKUP($B10,'Hospitalisation Details'!A9:J2353,10,0) -> 37589 | O10: =VLOOKUP($B10,'Hospitalisation Details'!A9:J2353,8,0) -> tier - 2 | P10: =VLOOKUP($B10,'Hospitalisation Details'!A9:J2353,7,0) -> tier - 3 | Q10: =VLOOKUP($B10,'Hospitalisation Details'!A9:J2353,9,0) -> R1012 | R10: =VLOOKUP($B10,'Hospitalisation Details'!A9:K2353,11,0) -> 20
A11: Id10 | B11: Id2326 | C11: =VLOOKUP($A11,'Customer Names'!$A:$E,4,FALSE) -> Brooke N. | D11: =VLOOKUP($A11,'Medical Examinations'!$A:$J,2,FALSE) -> Obesity | E11: =VLOOKUP($A11,'Medical Examinations'!$A:$J,4,FALSE) -> 10.79 | F11: =VLOOKUP($A11,'Medical Examinations'!$A:$J,6,FALSE) -> No | G11: =VLOOKUP($A11,'Medical Examinations'!$A:$J,7,FALSE) -> No | H11: =VLOOKUP($A11,'Medical Examinations'!$A:$J,8,FALSE) -> No | I11: =VLOOKUP($A11,'Medical Examinations'!$A:$J,9,FALSE) -> 0 | J11: =VLOOKUP($A11,'Medical Examinations'!$A:$J,10,FALSE) -> yes | K11: =VLOOKUP($A11,'Medical Examinations'!$A:$J,5,FALSE) -> Diabetes | L11: =VLOOKUP($A12,'Medical Examinations'!$A:$J,3,FALSE) -> 37.7 | M11: =VLOOKUP($A11,'Hospitalisation Details'!$A:$K,6,FALSE) -> 48885.14 | N11: =VLOOKUP($B11,'Hospitalisation Details'!A10:J2354,10,0) -> 35743 | O11: =VLOOKUP($B11,'Hospitalisation Details'!A10:J2354,8,0) -> tier - 3 | P11: =VLOOKUP($B11,'Hospitalisation Details'!A10:J2354,7,0) -> tier - 3 | Q11: =VLOOKUP($B11,'Hospitalisation Details'!A10:J2354,9,0) -> R1013 | R11: =VLOOKUP($B11,'Hospitalisation Details'!A10:K2354,11,0) -> 25
A12: Id11 | B12: Id2325 | C12: =VLOOKUP($A12,'Customer Names'!$A:$E,4,FALSE) -> Paola Andrea | D12: =VLOOKUP($A12,'Medical Examinations'!$A:$J,2,FALSE) -> Obesity | E12: =VLOOKUP($A12,'Medical Examinations'!$A:$J,4,FALSE) -> 5.96 | F12: =VLOOKUP($A12,'Medical Examinations'!$A:$J,6,FALSE) -> yes | G12: =VLOOKUP($A12,'Medical Examinations'!$A:$J,7,FALSE) -> No | H12: =VLOOKUP($A12,'Medical Examinations'!$A:$J,8,FALSE) -> No | I12: =VLOOKUP($A12,'Medical Examinations'!$A:$J,9,FALSE) -> 0 | J12: =VLOOKUP($A12,'Medical Examinations'!$A:$J,10,FALSE) -> yes | K12: =VLOOKUP($A12,'Medical Examinations'!$A:$J,5,FALSE) -> Prediabetes | L12: =VLOOKUP($A13,'Medical Examinations'!$A:$J,3,FALSE) -> 42.13 | M12: =VLOOKUP($A12,'Hospitalisation Details'!$A:$K,6,FALSE) -> 48824.45 | N12: =VLOOKUP($B12,'Hospitalisation Details'!A11:J2355,10,0) -> 37146 | O12: =VLOOKUP($B12,'Hospitalisation Details'!A11:J2355,8,0) -> tier - 2 | P12: =VLOOKUP($B12,'Hospitalisation Details'!A11:J2355,7,0) -> tier - 3 | Q12: =VLOOKUP($B12,'Hospitalisation Details'!A11:J2355,9,0) -> R1013 | R12: =VLOOKUP($B12,'Hospitalisation Details'!A11:K2355,11,0) -> 21
A13: Id12 | B13: Id2324 | C13: =VLOOKUP($A13,'Customer Names'!$A:$E,4,FALSE) -> David | D13: =VLOOKUP($A13,'Medical Examinations'!$A:$J,2,FALSE) -> Obesity | E13: =VLOOKUP($A13,'Medical Examinations'!$A:$J,4,FALSE) -> 11.9 | F13: =VLOOKUP($A13,'Medical Examinations'!$A:$J,6,FALSE) -> No | G13: =VLOOKUP($A13,'Medical Examinations'!$A:$J,7,FALSE) -> No | H13: =VLOOKUP($A13,'Medical Examinations'!$A:$J,8,FALSE) -> No | I13: =VLOOKUP($A13,'Medical Examinations'!$A:$J,9,FALSE) -> 2 | J13: =VLOOKUP($A13,'Medical Examinations'!$A:$J,10,FALSE) -> yes | K13: =VLOOKUP($A13,'Medical Examinations'!$A:$J,5,FALSE) -> Diabetes | L13: =VLOOKUP($A14,'Medical Examinations'!$A:$J,3,FALSE) -> 40.92 | M13: =VLOOKUP($A13,'Hospitalisation Details'!$A:$K,6,FALSE) -> 48675.52 | N13: =VLOOKUP($B13,'Hospitalisation Details'!A12:J2356,10,0) -> 36520 | O13: =VLOOKUP($B13,'Hospitalisation Details'!A12:J2356,8,0) -> tier - 3 | P13: =VLOOKUP($B13,'Hospitalisation Details'!A12:J2356,7,0) -> tier - 2 | Q13: =VLOOKUP($B13,'Hospitalisation Details'!A12:J2356,9,0) -> R1013 | R13: =VLOOKUP($B13,'Hospitalisation Details'!A12:K2356,11,0) -> 23
A14: Id13 | B14: Id2323 | C14: =VLOOKUP($A14,'Customer Names'!$A:$E,4,FALSE) -> Wade | D14: =VLOOKUP($A14,'Medical Examinations'!$A:$J,2,FALSE) -> Obesity | E14: =VLOOKUP($A14,'Medical Examinations'!$A:$J,4,FALSE) -> 8.41 | F14: =VLOOKUP($A14,'Medical Examinations'!$A:$J,6,FALSE) -> No | G14: =VLOOKUP($A14,'Medical Examinations'!$A:$J,7,FALSE) -> No | H14: =VLOOKUP($A14,'Medical Examinations'!$A:$J,8,FALSE) -> No | I14: =VLOOKUP($A14,'Medical Examinations'!$A:$J,9,FALSE) -> 0 | J14: =VLOOKUP($A14,'Medical Examinations'!$A:$J,10,FALSE) -> yes | K14: =VLOOKUP($A14,'Medical Examinations'!$A:$J,5,FALSE) -> Diabetes | L14: =VLOOKUP($A15,'Medical Examinations'!$A:$J,3,FALSE) -> 40.565 | M14: =VLOOKUP($A14,'Hospitalisation Details'!$A:$K,6,FALSE) -> 48673.56 | N14: =VLOOKUP($B14,'Hospitalisation Details'!A13:J2357,10,0) -> 36508 | O14: =VLOOKUP($B14,'Hospitalisation Details'!A13:J2357,8,0) -> tier - 1 | P14: =VLOOKUP($B14,'Hospitalisation Details'!A13:J2357,7,0) -> tier - 3 | Q14: =VLOOKUP($B14,'Hospitalisation Details'!A13:J2357,9,0) -> R1013 | R14: =VLOOKUP($B14,'Hospitalisation Details'!A13:K2357,11,0) -> 23
... A1593: Id1592 | B1593: Id747 | C1593: =VLOOKUP($A1593,'Customer Names'!$A:$E,4,FALSE) -> Lawrence | D1593: =VLOOKUP($A1593,'Medical Examinations'!$A:$J,2,FALSE) -> Overweight | E1593: =VLOOKUP($A1593,'Medical Examinations'!$A:$J,4,FALSE) -> 11.41 | F1593: =VLOOKUP($A1593,'Medical Examinations'!$A:$J,6,FALSE) -> yes | G1593: =VLOOKUP($A1593,'Medical Examinations'!$A:$J,7,FALSE) -> No | H1593: =VLOOKUP($A1593,'Medical Examinations'!$A:$J,8,FALSE) -> No | I1593: =VLOOKUP($A1593,'Medical Examinations'!$A:$J,9,FALSE) -> 0 | J1593: =VLOOKUP($A1593,'Medical Examinations'!$A:$J,10,FALSE) -> No | K1593: =VLOOKUP($A1593,'Medical Examinations'!$A:$J,5,FALSE) -> Diabetes | L1593: =VLOOKUP($A1594,'Medical Examinations'!$A:$J,3,FALSE) -> 31.74 | M1593: =VLOOKUP($A1593,'Hospitalisation Details'!$A:$K,6,FALSE) -> 6282.24 | N1593: =VLOOKUP($B1593,'Hospitalisation Details'!A1592:J3936,10,0) -> 31304 | O1593: =VLOOKUP($B1593,'Hospitalisation Details'!A1592:J3936,8,0) -> tier - 1 | P1593: =VLOOKUP($B1593,'Hospitalisation Details'!A1592:J3936,7,0) -> tier - 3 | Q1593: =VLOOKUP($B1593,'Hospitalisation Details'!A1592:J3936,9,0) -> R1026 | R1593: =VLOOKUP($B1593,'Hospitalisation Details'!A1592:K3936,11,0) -> 37
A1594: Id1593 | B1594: Id746 | C1594: =VLOOKUP($A1594,'Customer Names'!$A:$E,4,FALSE) -> Katie | D1594: =VLOOKUP($A1594,'Medical Examinations'!$A:$J,2,FALSE) -> Obesity | E1594: =VLOOKUP($A1594,'Medical Examinations'!$A:$J,4,FALSE) -> 4.46 | F1594: =VLOOKUP($A1594,'Medical Examinations'!$A:$J,6,FALSE) -> No | G1594: =VLOOKUP($A1594,'Medical Examinations'!$A:$J,7,FALSE) -> No | H1594: =VLOOKUP($A1594,'Medical Examinations'!$A:$J,8,FALSE) -> Yes | I1594: =VLOOKUP($A1594,'Medical Examinations'!$A:$J,9,FALSE) -> 1 | J1594: =VLOOKUP($A1594,'Medical Examinations'!$A:$J,10,FALSE) -> No | K1594: =VLOOKUP($A1594,'Medical Examinations'!$A:$J,5,FALSE) -> Normal | L1594: =VLOOKUP($A1595,'Medical Examinations'!$A:$J,3,FALSE) -> 21.78 | N1594: =VLOOKUP($B1594,'Hospitalisation Details'!A1593:J3937,10,0) -> 31740 | O1594: =VLOOKUP($B1594,'Hospitalisation Details'!A1593:J3937,8,0) -> tier - 2 | P1594: =VLOOKUP($B1594,'Hospitalisation Details'!A1593:J3937,7,0) -> tier - 3 | Q1594: =VLOOKUP($B1594,'Hospitalisation Details'!A1593:J3937,9,0) -> R1023 | R1594: =VLOOKUP($B1594,'Hospitalisation Details'!A1593:K3937,11,0) -> 36
A1595: Id1594 | B1595: Id745 | C1595: =VLOOKUP($A1595,'Customer Names'!$A:$E,4,FALSE) -> Ruben | D1595: =VLOOKUP($A1595,'Medical Examinations'!$A:$J,2,FALSE) -> Normal Weight | E1595: =VLOOKUP($A1595,'Medical Examinations'!$A:$J,4,FALSE) -> 9.31 | F1595: =VLOOKUP($A1595,'Medical Examinations'!$A:$J,6,FALSE) -> yes | G1595: =VLOOKUP($A1595,'Medical Examinations'!$A:$J,7,FALSE) -> No | H1595: =VLOOKUP($A1595,'Medical Examinations'!$A:$J,8,FALSE) -> No | I1595: =VLOOKUP($A1595,'Medical Examinations'!$A:$J,9,FALSE) -> 0 | J1595: =VLOOKUP($A1595,'Medical Examinations'!$A:$J,10,FALSE) -> No | K1595: =VLOOKUP($A1595,'Medical Examinations'!$A:$J,5,FALSE) -> Diabetes | L1595: =VLOOKUP($A1596,'Medical Examinations'!$A:$J,3,FALSE) -> 23.75 | N1595: =VLOOKUP($B1595,'Hospitalisation Details'!A1594:J3938,10,0) -> 29800 | O1595: =VLOOKUP($B1595,'Hospitalisation Details'!A1594:J3938,8,0) -> tier - 2 | P1595: =VLOOKUP($B1595,'Hospitalisation Details'!A1594:J3938,7,0) -> tier - 3 | Q1595: =VLOOKUP($B1595,'Hospitalisation Details'!A1594:J3938,9,0) -> R1024 | R1595: =VLOOKUP($B1595,'Hospitalisation Details'!A1594:K3938,11,0) -> 41
A1596: Id1595 | B1596: Id744 | C1596: =VLOOKUP($A1596,'Customer Names'!$A:$E,4,FALSE) -> Sarah | D1596: =VLOOKUP($A1596,'Medical Examinations'!$A:$J,2,FALSE) -> Normal Weight | E1596: =VLOOKUP($A1596,'Medical Examinations'!$A:$J,4,FALSE) -> 5.03 | F1596: =VLOOKUP($A1596,'Medical Examinations'!$A:$J,6,FALSE) -> No | G1596: =VLOOKUP($A1596,'Medical Examinations'!$A:$J,7,FALSE) -> No | H1596: =VLOOKUP($A1596,'Medical Examinations'!$A:$J,8,FALSE) -> No | I1596: =VLOOKUP($A1596,'Medical Examinations'!$A:$J,9,FALSE) -> 1 | J1596: =VLOOKUP($A1596,'Medical Examinations'!$A:$J,10,FALSE) -> No | K1596: =VLOOKUP($A1596,'Medical Examinations'!$A:$J,5,FALSE) -> Normal | L1596: =VLOOKUP($A1597,'Medical Examinations'!$A:$J,3,FALSE) -> 33.21 | N1596: =VLOOKUP($B1596,'Hospitalisation Details'!A1595:J3939,10,0) -> 31288 | O1596: =VLOOKUP($B1596,'Hospitalisation Details'!A1595:J3939,8,0) -> tier - 3 | P1596: =VLOOKUP($B1596,'Hospitalisation Details'!A1595:J3939,7,0) -> tier - 3 | Q1596: =VLOOKUP($B1596,'Hospitalisation Details'!A1595:J3939,9,0) -> R1026 | R1596: =VLOOKUP($B1596,'Hospitalisation Details'!A1595:K3939,11,0) -> 37
A1597: Id1596 | B1597: Id743 | C1597: =VLOOKUP($A1597,'Customer Names'!$A:$E,4,FALSE) -> Angela R. | D1597: =VLOOKUP($A1597,'Medical Examinations'!$A:$J,2,FALSE) -> Obesity | E1597: =VLOOKUP($A1597,'Medical Examinations'!$A:$J,4,FALSE) -> 5.07 | F1597: =VLOOKUP($A1597,'Medical Examinations'!$A:$J,6,FALSE) -> yes | G1597: =VLOOKUP($A1597,'Medical Examinations'!$A:$J,7,FALSE) -> No | H1597: =VLOOKUP($A1597,'Medical Examinations'!$A:$J,8,FALSE) -> No | I1597: =VLOOKUP($A1597,'Medical Examinations'!$A:$J,9,FALSE) -> 1 | J1597: =VLOOKUP($A1597,'Medical Examinations'!$A:$J,10,FALSE) -> No | K1597: =VLOOKUP($A1597,'Medical Examinations'!$A:$J,5,FALSE) -> Normal | L1597: =VLOOKUP($A1598,'Medical Examinations'!$A:$J,3,FALSE) -> 17.7 | N1597: =VLOOKUP($B1597,'Hospitalisation Details'!A1596:J3940,10,0) -> 25499 | O1597: =VLOOKUP($B1597,'Hospitalisation Details'!A1596:J3940,8,0) -> tier - 2 | P1597: =VLOOKUP($B1597,'Hospitalisation Details'!A1596:J3940,7,0) -> tier - 3 | Q1597: =VLOOKUP($B1597,'Hospitalisation Details'!A1596:J3940,9,0) -> R1026 | R1597: =VLOOKUP($B1597,'Hospitalisation Details'!A1596:K3940,11,0) -> 53
A1598: Id1597 | B1598: Id742 | C1598: =VLOOKUP($A1598,'Customer Names'!$A:$E,4,FALSE) -> Chatham | D1598: =VLOOKUP($A1598,'Medical Examinations'!$A:$J,2,FALSE) -> Underweight | E1598: =VLOOKUP($A1598,'Medical Examinations'!$A:$J,4,FALSE) -> 10.42 | F1598: =VLOOKUP($A1598,'Medical Examinations'!$A:$J,6,FALSE) -> yes | G1598: =VLOOKUP($A1598,'Medical Examinations'!$A:$J,7,FALSE) -> No | H1598: =VLOOKUP($A1598,'Medical Examinations'!$A:$J,8,FALSE) -> No | I1598: =VLOOKUP($A1598,'Medical Examinations'!$A:$J,9,FALSE) -> 2 | J1598: =VLOOKUP($A1598,'Medical Examinations'!$A:$J,10,FALSE) -> No | K1598: =VLOOKUP($A1598,'Medical Examinations'!$A:$J,5,FALSE) -> Diabetes | L1598: =VLOOKUP($A1599,'Medical Examinations'!$A:$J,3,FALSE) -> 17.2 | N1598: =VLOOKUP($B1598,'Hospitalisation Details'!A1597:J3941,10,0) -> 38184 | O1598: =VLOOKUP($B1598,'Hospitalisation Details'!A1597:J3941,8,0) -> tier - 2 | P1598: =VLOOKUP($B1598,'Hospitalisation Details'!A1597:J3941,7,0) -> tier - 3 | Q1598: =VLOOKUP($B1598,'Hospitalisation Details'!A1597:J3941,9,0) -> R1018 | R1598: =VLOOKUP($B1598,'Hospitalisation Details'!A1597:K3941,11,0) -> 18
A1599: Id1598 | B1599: Id741 | C1599: =VLOOKUP($A1599,'Customer Names'!$A:$E,4,FALSE) -> Derek | D1599: =VLOOKUP($A1599,'Medical Examinations'!$A:$J,2,FALSE) -> Underweight | E1599: =VLOOKUP($A1599,'Medical Examinations'!$A:$J,4,FALSE) -> 6.45 | F1599: =VLOOKUP($A1599,'Medical Examinations'!$A:$J,6,FALSE) -> No | G1599: =VLOOKUP($A1599,'Medical Examinations'!$A:$J,7,FALSE) -> No | H1599: =VLOOKUP($A1599,'Medical Examinations'!$A:$J,8,FALSE) -> No | I1599: =VLOOKUP($A1599,'Medical Examinations'!$A:$J,9,FALSE) -> 2 | J1599: =VLOOKUP($A1599,'Medical Examinations'!$A:$J,10,FALSE) -> No | K1599: =VLOOKUP($A1599,'Medical Examinations'!$A:$J,5,FALSE) -> Prediabetes | L1599: =VLOOKUP($A1600,'Medical Examinations'!$A:$J,3,FALSE) -> 19.21 | N1599: =VLOOKUP($B1599,'Hospitalisation Details'!A1598:J3942,10,0) -> 21768 | O1599: =VLOOKUP($B1599,'Hospitalisation Details'!A1598:J3942,8,0) -> tier - 1 | P1599: =VLOOKUP($B1599,'Hospitalisation Details'!A1598:J3942,7,0) -> tier - 3 | Q1599: =VLOOKUP($B1599,'Hospitalisation Details'!A1598:J3942,9,0) -> R1012 | R1599: =VLOOKUP($B1599,'Hospitalisation Details'!A1598:K3942,11,0) -> 63
A1600: Id1599 | B1600: Id740 | C1600: =VLOOKUP($A1600,'Customer Names'!$A:$E,4,FALSE) -> Kalvin J. | D1600: =VLOOKUP($A1600,'Medical Examinations'!$A:$J,2,FALSE) -> Normal Weight | E1600: =VLOOKUP($A1600,'Medical Examinations'!$A:$J,4,FALSE) -> 5.52 | F1600: =VLOOKUP($A1600,'Medical Examinations'!$A:$J,6,FALSE) -> No | G1600: =VLOOKUP($A1600,'Medical Examinations'!$A:$J,7,FALSE) -> No | H1600: =VLOOKUP($A1600,'Medical Examinations'!$A:$J,8,FALSE) -> No | I1600: =VLOOKUP($A1600,'Medical Examinations'!$A:$J,9,FALSE) -> 2 | J1600: =VLOOKUP($A1600,'Medical Examinations'!$A:$J,10,FALSE) -> No | K1600: =VLOOKUP($A1600,'Medical Examinations'!$A:$J,5,FALSE) -> Normal | L1600: =VLOOKUP($A1601,'Medical Examinations'!$A:$J,3,FALSE) -> 23.2 | N1600: =VLOOKUP($B1600,'Hospitalisation Details'!A1599:J3943,10,0) -> 24421 | O1600: =VLOOKUP($B1600,'Hospitalisation Details'!A1599:J3943,8,0) -> tier - 3 | P1600: =VLOOKUP($B1600,'Hospitalisation Details'!A1599:J3943,7,0) -> tier - 3 | Q1600: =VLOOKUP($B1600,'Hospitalisation Details'!A1599:J3943,9,0) -> R1026 | R1600: =VLOOKUP($B1600,'Hospitalisation Details'!A1599:K3943,11,0) -> 56
A1601: Id1600 | B1601: Id739 | C1601: =VLOOKUP($A1601,'Customer Names'!$A:$E,4,FALSE) -> Dave | D1601: =VLOOKUP($A1601,'Medical Examinations'!$A:$J,2,FALSE) -> Normal Weight | E1601: =VLOOKUP($A1601,'Medical Examinations'!$A:$J,4,FALSE) -> 4.41 | F1601: =VLOOKUP($A1601,'Medical Examinations'!$A:$J,6,FALSE) -> No | G1601: =VLOOKUP($A1601,'Medical Examinations'!$A:$J,7,FALSE) -> No | H1601: =VLOOKUP($A1601,'Medical Examinations'!$A:$J,8,FALSE) -> Yes | I1601: =VLOOKUP($A1601,'Medical Examinations'!$A:$J,9,FALSE) -> 1 | J1601: =VLOOKUP($A1601,'Medical Examinations'!$A:$J,10,FALSE) -> No | K1601: =VLOOKUP($A1601,'Medical Examinations'!$A:$J,5,FALSE) -> Normal | L1601: =VLOOKUP($A1602,'Medical Examinations'!$A:$J,3,FALSE) -> 32.5 | N1601: =VLOOKUP($B1601,'Hospitalisation Details'!A1600:J3944,10,0) -> 31754 | O1601: =VLOOKUP($B1601,'Hospitalisation Details'!A1600:J3944,8,0) -> tier - 2 | P1601: =VLOOKUP($B1601,'Hospitalisation Details'!A1600:J3944,7,0) -> tier - 3 | Q1601: =VLOOKUP($B1601,'Hospitalisation Details'!A1600:J3944,9,0) -> R1012 | R1601: =VLOOKUP($B1601,'Hospitalisation Details'!A1600:K3944,11,0) -> 36
A1602: Id1601 | B1602: Id738 | C1602: =VLOOKUP($A1602,'Customer Names'!$A:$E,4,FALSE) -> Barbara G. | D1602: =VLOOKUP($A1602,'Medical Examinations'!$A:$J,2,FALSE) -> Obesity | E1602: =VLOOKUP($A1602,'Medical Examinations'!$A:$J,4,FALSE) -> 4.69 | F1602: =VLOOKUP($A1602,'Medical Examinations'!$A:$J,6,FALSE) -> yes | G1602: =VLOOKUP($A1602,'Medical Examinations'!$A:$J,7,FALSE) -> No | H1602: =VLOOKUP($A1602,'Medical Examinations'!$A:$J,8,FALSE) -> Yes | I1602: =VLOOKUP($A1602,'Medical Examinations'!$A:$J,9,FALSE) -> 1 | J1602: =VLOOKUP($A1602,'Medical Examinations'!$A:$J,10,FALSE) -> No | K1602: =VLOOKUP($A1602,'Medical Examinations'!$A:$J,5,FALSE) -> Normal | L1602: =VLOOKUP($A1603,'Medical Examinations'!$A:$J,3,FALSE) -> 20.9 | N1602: =VLOOKUP($B1602,'Hospitalisation Details'!A1601:J3945,10,0) -> 21514 | O1602: =VLOOKUP($B1602,'Hospitalisation Details'!A1601:J3945,8,0) -> tier - 3 | P1602: =VLOOKUP($B1602,'Hospitalisation Details'!A1601:J3945,7,0) -> tier - 3 | Q1602: =VLOOKUP($B1602,'Hospitalisation Details'!A1601:J3945,9,0) -> R1011 | R1602: =VLOOKUP($B1602,'Hospitalisation Details'!A1601:K3945,11,0) -> 64
A1603: Id1602 | B1603: Id737 | C1603: =VLOOKUP($A1603,'Customer Names'!$A:$E,4,FALSE) -> Skylar | D1603: =VLOOKUP($A1603,'Medical Examinations'!$A:$J,2,FALSE) -> Normal Weight | E1603: =VLOOKUP($A1603,'Medical Examinations'!$A:$J,4,FALSE) -> 6.94 | F1603: =VLOOKUP($A1603,'Medical Examinations'!$A:$J,6,FALSE) -> No | G1603: =VLOOKUP($A1603,'Medical Examinations'!$A:$J,7,FALSE) -> No | H1603: =VLOOKUP($A1603,'Medical Examinations'!$A:$J,8,FALSE) -> No | I1603: =VLOOKUP($A1603,'Medical Examinations'!$A:$J,9,FALSE) -> 0 | J1603: =VLOOKUP($A1603,'Medical Examinations'!$A:$J,10,FALSE) -> No | K1603: =VLOOKUP($A1603,'Medical Examinations'!$A:$J,5,FALSE) -> Diabetes | L1603: =VLOOKUP($A1604,'Medical Examinations'!$A:$J,3,FALSE) -> 19.11 | N1603: =VLOOKUP($B1603,'Hospitalisation Details'!A1602:J3946,10,0) -> 21529 | O1603: =VLOOKUP($B1603,'Hospitalisation Details'!A1602:J3946,8,0) -> tier - 1 | P1603: =VLOOKUP($B1603,'Hospitalisation Details'!A1602:J3946,7,0) -> tier - 3 | Q1603: =VLOOKUP($B1603,'Hospitalisation Details'!A1602:J3946,9,0) -> R1013 | R1603: =VLOOKUP($B1603,'Hospitalisation Details'!A1602:K3946,11,0) -> 64
A1604: Id1603 | B1604: Id736 | C1604: =VLOOKUP($A1604,'Customer Names'!$A:$E,4,FALSE) -> Nick | D1604: =VLOOKUP($A1604,'Medical Examinations'!$A:$J,2,FALSE) -> Normal Weight | E1604: =VLOOKUP($A1604,'Medical Examinations'!$A:$J,4,FALSE) -> 4.35 | F1604: =VLOOKUP($A1604,'Medical Examinations'!$A:$J,6,FALSE) -> No | G1604: =VLOOKUP($A1604,'Medical Examinations'!$A:$J,7,FALSE) -> No | H1604: =VLOOKUP($A1604,'Medical Examinations'!$A:$J,8,FALSE) -> No | I1604: =VLOOKUP($A1604,'Medical Examinations'!$A:$J,9,FALSE) -> 2 | J1604: =VLOOKUP($A1604,'Medical Examinations'!$A:$J,10,FALSE) -> No | K1604: =VLOOKUP($A1604,'Medical Examinations'!$A:$J,5,FALSE) -> Normal | L1604: =VLOOKUP($A1605,'Medical Examinations'!$A:$J,3,FALSE) -> 31.17 | N1604: =VLOOKUP($B1604,'Hospitalisation Details'!A1603:J3947,10,0) -> 37779 | O1604: =VLOOKUP($B1604,'Hospitalisation Details'!A1603:J3947,8,0) -> tier - 1 | P1604: =VLOOKUP($B1604,'Hospitalisation Details'!A1603:J3947,7,0) -> tier - 2 | Q1604: =VLOOKUP($B1604,'Hospitalisation Details'!A1603:J3947,9,0) -> R1011 | R1604: =VLOOKUP($B1604,'Hospitalisation Details'!A1603:K3947,11,0) -> 20
A1605: Id1604 | B1605: Id735 | C1605: =VLOOKUP($A1605,'Customer Names'!$A:$E,4,FALSE) -> Sunny S | D1605: =VLOOKUP($A1605,'Medical Examinations'!$A:$J,2,FALSE) -> Obesity | E1605: =VLOOKUP($A1605,'Medical Examinations'!$A:$J,4,FALSE) -> 5.28 | F1605: =VLOOKUP($A1605,'Medical Examinations'!$A:$J,6,FALSE) -> No | G1605: =VLOOKUP($A1605,'Medical Examinations'!$A:$J,7,FALSE) -> No | H1605: =VLOOKUP($A1605,'Medical Examinations'!$A:$J,8,FALSE) -> No | I1605: =VLOOKUP($A1605,'Medical Examinations'!$A:$J,9,FALSE) -> 1 | J1605: =VLOOKUP($A1605,'Medical Examinations'!$A:$J,10,FALSE) -> No | K1605: =VLOOKUP($A1605,'Medical Examinations'!$A:$J,5,FALSE) -> Normal | L1605: =VLOOKUP($A1606,'Medical Examinations'!$A:$J,3,FALSE) -> 36.08 | N1605: =VLOOKUP($B1605,'Hospitalisation Details'!A1604:J3948,10,0) -> 22118 | O1605: =VLOOKUP($B1605,'Hospitalisation Details'!A1604:J3948,8,0) -> tier - 2 | P1605: =VLOOKUP($B1605,'Hospitalisation Details'!A1604:J3948,7,0) -> tier - 2 | Q1605: =VLOOKUP($B1605,'Hospitalisation Details'!A1604:J3948,9,0) -> R1012 | R1605: =VLOOKUP($B1605,'Hospitalisation Details'!A1604:K3948,11,0) -> 62
... A2336: Id2335 | B2336: Id9 | C2336: =VLOOKUP($A2336,'Customer Names'!$A:$E,4,FALSE) -> Aaron K | D2336: =VLOOKUP($A2336,'Medical Examinations'!$A:$J,2,FALSE) -> Underweight | E2336: =VLOOKUP($A2336,'Medical Examinations'!$A:$J,4,FALSE) -> 4.51 | F2336: =VLOOKUP($A2336,'Medical Examinations'!$A:$J,6,FALSE) -> No | G2336: =VLOOKUP($A2336,'Medical Examinations'!$A:$J,7,FALSE) -> No | H2336: =VLOOKUP($A2336,'Medical Examinations'!$A:$J,8,FALSE) -> No | I2336: =VLOOKUP($A2336,'Medical Examinations'!$A:$J,9,FALSE) -> 1 | J2336: =VLOOKUP($A2336,'Medical Examinations'!$A:$J,10,FALSE) -> No | K2336: =VLOOKUP($A2336,'Medical Examinations'!$A:$J,5,FALSE) -> Normal | L2336: =VLOOKUP($A2337,'Medical Examinations'!$A:$J,3,FALSE) -> 0 | N2336: =VLOOKUP($B2336,'Hospitalisation Details'!A2335:J4679,10,0) -> 23258 | O2336: =VLOOKUP($B2336,'Hospitalisation Details'!A2335:J4679,8,0) -> tier - 2 | P2336: =VLOOKUP($B2336,'Hospitalisation Details'!A2335:J4679,7,0) -> tier - 1 | Q2336: =VLOOKUP($B2336,'Hospitalisation Details'!A2335:J4679,9,0) -> R1013 | R2336: =VLOOKUP($B2336,'Hospitalisation Details'!A2335:K4679,11,0) -> 59
A2337: =COUNTIF(A2:A2336,"?") -> 0 | B2337: Id8
B2338: Id7
B2339: Id6
B2340: Id5
B2341: Id4
B2342: Id3
B2343: Id2
B2344: Id1
B2345: =COUNTIF(B2:B2344,"?") -> 6
